Workbook
Name SlicerCache_Table_1_Col_13: #N/A

Sheet data on outstanding creditors
A1: รหัส-แผน | B1: วันที่ตรวจรับของ | C1: ชื่อเจ้าหนี้ | D1: เลขที่ใบส่งของ | E1: จำนวนเงิน | F1: จ่าย | G1: ปรับปรุง เจ้าหนี้ | H1: คงเหลือ | I1: วันที่ชำระเงิน | J1: อื่นๆ | K1: รับเอกสาร | L1: หมายเหตุ | M1: ค่า | N1: หน่วยงาน | O1: Goods Value | P1: Vat 7 % | Q1: วันที่ตรวจรับของ2 | R1: วันที่ตรวจรับของ3 | S1: วันที่ตรวจรับของ4 | T1: กันซ้ำ
B2: 45695 | C2: บ.พีเอ็มแอล ฟาร์มาซูติคอลส์ | D2: SIS250205-084 | E2: 15000 | F2: 15000 | H2: ='data on outstanding creditors'!$E2-'data on outstanding creditors'!$F2-'data on outstanding creditors'!$G2 -> 0 | I2: 45938 | M2: 2.1.01 ค่ายา | N2: กลุ่มงาน เภสัชกรรม | O2: ='data on outstanding creditors'!$E2*100/107 -> 14018.692 | P2: ='data on outstanding creditors'!$E2-'data on outstanding creditors'!$O2 -> 981.30841 | Q2: =DAY('data on outstanding creditors'!$B2) -> 7 | R2: =MONTH('data on outstanding creditors'!$B2) -> 2 | S2: =YEAR('data on outstanding creditors'!$B2) -> 2025 | T2: ='data on outstanding creditors'!$C2&" "&'data on outstanding creditors'!$D2&" "&TEXT('data on outstanding creditors'!$E2,"#,##0.00") -> บ.พีเอ็มแอล ฟาร์มาซูติคอลส์ SIS250205-084 15,000.00
B3: 45734 | C3: บ.เซ็นทรัลโพลีเทรดดิ้ง | D3: 31i25013722 | E3: 43980 | F3: 43980 | H3: ='data on outstanding creditors'!$E3-'data on outstanding creditors'!$F3-'data on outstanding creditors'!$G3 -> 0 | I3: 45938 | M3: 2.1.01 ค่ายา | N3: กลุ่มงาน เภสัชกรรม | O3: ='data on outstanding creditors'!$E3*100/107 -> 41102.804 | P3: ='data on outstanding creditors'!$E3-'data on outstanding creditors'!$O3 -> 2877.1963 | Q3: =DAY('data on outstanding creditors'!$B3) -> 18 | R3: =MONTH('data on outstanding creditors'!$B3) -> 3 | S3: =YEAR('data on outstanding creditors'!$B3) -> 2025 | T3: ='data on outstanding creditors'!$C3&" "&'data on outstanding creditors'!$D3&" "&TEXT('data on outstanding creditors'!$E3,"#,##0.00") -> บ.เซ็นทรัลโพลีเทรดดิ้ง 31i25013722 43,980.00
B4: 45734 | C4: บ.เซ็นทรัลโพลีเทรดดิ้ง | D4: 31i25014076 | E4: 48000 | F4: 48000 | H4: ='data on outstanding creditors'!$E4-'data on outstanding creditors'!$F4-'data on outstanding creditors'!$G4 -> 0 | I4: 45938 | M4: 2.1.01 ค่ายา | N4: กลุ่มงาน เภสัชกรรม | O4: ='data on outstanding creditors'!$E4*100/107 -> 44859.813 | P4: ='data on outstanding creditors'!$E4-'data on outstanding creditors'!$O4 -> 3140.1869 | Q4: =DAY('data on outstanding creditors'!$B4) -> 18 | R4: =MONTH('data on outstanding creditors'!$B4) -> 3 | S4: =YEAR('data on outstanding creditors'!$B4) -> 2025 | T4: ='data on outstanding creditors'!$C4&" "&'data on outstanding creditors'!$D4&" "&TEXT('data on outstanding creditors'!$E4,"#,##0.00") -> บ.เซ็นทรัลโพลีเทรดดิ้ง 31i25014076 48,000.00
B5: 45737 | C5: บ.เซ็นทรัลโพลีเทรดดิ้ง | D5: 31i25015092 | E5: 55000 | F5: 55000 | H5: ='data on outstanding creditors'!$E5-'data on outstanding creditors'!$F5-'data on outstanding creditors'!$G5 -> 0 | I5: 45938 | M5: 2.1.01 ค่ายา | N5: กลุ่มงาน เภสัชกรรม | O5: ='data on outstanding creditors'!$E5*100/107 -> 51401.869 | P5: ='data on outstanding creditors'!$E5-'data on outstanding creditors'!$O5 -> 3598.1308 | Q5: =DAY('data on outstanding creditors'!$B5) -> 21 | R5: =MONTH('data on outstanding creditors'!$B5) -> 3 | S5: =YEAR('data on outstanding creditors'!$B5) -> 2025 | T5: ='data on outstanding creditors'!$C5&" "&'data on outstanding creditors'!$D5&" "&TEXT('data on outstanding creditors'!$E5,"#,##0.00") -> บ.เซ็นทรัลโพลีเทรดดิ้ง 31i25015092 55,000.00
B6: 45742 | C6: บ.เซ็นทรัลโพลีเทรดดิ้ง | D6: 31i25016112 | E6: 68000 | F6: 68000 | H6: ='data on outstanding creditors'!$E6-'data on outstanding creditors'!$F6-'data on outstanding creditors'!$G6 -> 0 | I6: 45938 | M6: 2.1.01 ค่ายา | N6: กลุ่มงาน เภสัชกรรม | O6: ='data on outstanding creditors'!$E6*100/107 -> 63551.402 | P6: ='data on outstanding creditors'!$E6-'data on outstanding creditors'!$O6 -> 4448.5981 | Q6: =DAY('data on outstanding creditors'!$B6) -> 26 | R6: =MONTH('data on outstanding creditors'!$B6) -> 3 | S6: =YEAR('data on outstanding creditors'!$B6) -> 2025 | T6: ='data on outstanding creditors'!$C6&" "&'data on outstanding creditors'!$D6&" "&TEXT('data on outstanding creditors'!$E6,"#,##0.00") -> บ.เซ็นทรัลโพลีเทรดดิ้ง 31i25016112 68,000.00
B7: 45742 | C7: บ.เซ็นทรัลโพลีเทรดดิ้ง | D7: 31i25016114 | E7: 28000 | F7: 28000 | H7: ='data on outstanding creditors'!$E7-'data on outstanding creditors'!$F7-'data on outstanding creditors'!$G7 -> 0 | I7: 45938 | M7: 2.1.01 ค่ายา | N7: กลุ่มงาน เภสัชกรรม | O7: ='data on outstanding creditors'!$E7*100/107 -> 26168.224 | P7: ='data on outstanding creditors'!$E7-'data on outstanding creditors'!$O7 -> 1831.7757 | Q7: =DAY('data on outstanding creditors'!$B7) -> 26 | R7: =MONTH('data on outstanding creditors'!$B7) -> 3 | S7: =YEAR('data on outstanding creditors'!$B7) -> 2025 | T7: ='data on outstanding creditors'!$C7&" "&'data on outstanding creditors'!$D7&" "&TEXT('data on outstanding creditors'!$E7,"#,##0.00") -> บ.เซ็นทรัลโพลีเทรดดิ้ง 31i25016114 28,000.00
B8: 45742 | C8: บ.เซ็นทรัลโพลีเทรดดิ้ง | D8: 31i25016391 | E8: 15000 | F8: 15000 | H8: ='data on outstanding creditors'!$E8-'data on outstanding creditors'!$F8-'data on outstanding creditors'!$G8 -> 0 | I8: 45938 | M8: 2.1.01 ค่ายา | N8: กลุ่มงาน เภสัชกรรม | O8: ='data on outstanding creditors'!$E8*100/107 -> 14018.692 | P8: ='data on outstanding creditors'!$E8-'data on outstanding creditors'!$O8 -> 981.30841 | Q8: =DAY('data on outstanding creditors'!$B8) -> 26 | R8: =MONTH('data on outstanding creditors'!$B8) -> 3 | S8: =YEAR('data on outstanding creditors'!$B8) -> 2025 | T8: ='data on outstanding creditors'!$C8&" "&'data on outstanding creditors'!$D8&" "&TEXT('data on outstanding creditors'!$E8,"#,##0.00") -> บ.เซ็นทรัลโพลีเทรดดิ้ง 31i25016391 15,000.00
B9: 45751 | C9: บ.เซ็นทรัลโพลีเทรดดิ้ง | D9: 31i25017963 | E9: 10000 | F9: 10000 | H9: ='data on outstanding creditors'!$E9-'data on outstanding creditors'!$F9-'data on outstanding creditors'!$G9 -> 0 | I9: 45938 | M9: 2.1.01 ค่ายา | N9: กลุ่มงาน เภสัชกรรม | O9: ='data on outstanding creditors'!$E9*100/107 -> 9345.7944 | P9: ='data on outstanding creditors'!$E9-'data on outstanding creditors'!$O9 -> 654.20561 | Q9: =DAY('data on outstanding creditors'!$B9) -> 4 | R9: =MONTH('data on outstanding creditors'!$B9) -> 4 | S9: =YEAR('data on outstanding creditors'!$B9) -> 2025 | T9: ='data on outstanding creditors'!$C9&" "&'data on outstanding creditors'!$D9&" "&TEXT('data on outstanding creditors'!$E9,"#,##0.00") -> บ.เซ็นทรัลโพลีเทรดดิ้ง 31i25017963 10,000.00
B10: 45758 | C10: บ.เซ็นทรัลโพลีเทรดดิ้ง | D10: 31i25018889 | E10: 43200 | F10: 43200 | H10: ='data on outstanding creditors'!$E10-'data on outstanding creditors'!$F10-'data on outstanding creditors'!$G10 -> 0 | I10: 45938 | M10: 2.1.01 ค่ายา | N10: กลุ่มงาน เภสัชกรรม | O10: ='data on outstanding creditors'!$E10*100/107 -> 40373.832 | P10: ='data on outstanding creditors'!$E10-'data on outstanding creditors'!$O10 -> 2826.1682 | Q10: =DAY('data on outstanding creditors'!$B10) -> 11 | R10: =MONTH('data on outstanding creditors'!$B10) -> 4 | S10: =YEAR('data on outstanding creditors'!$B10) -> 2025 | T10: ='data on outstanding creditors'!$C10&" "&'data on outstanding creditors'!$D10&" "&TEXT('data on outstanding creditors'!$E10,"#,##0.00") -> บ.เซ็นทรัลโพลีเทรดดิ้ง 31i25018889 43,200.00
B11: 45764 | C11: บ.เซ็นทรัลโพลีเทรดดิ้ง | D11: 31i25019285 | E11: 8250 | F11: 8250 | H11: ='data on outstanding creditors'!$E11-'data on outstanding creditors'!$F11-'data on outstanding creditors'!$G11 -> 0 | I11: 45938 | M11: 2.1.01 ค่ายา | N11: กลุ่มงาน เภสัชกรรม | O11: ='data on outstanding creditors'!$E11*100/107 -> 7710.2804 | P11: ='data on outstanding creditors'!$E11-'data on outstanding creditors'!$O11 -> 539.71963 | Q11: =DAY('data on outstanding creditors'!$B11) -> 17 | R11: =MONTH('data on outstanding creditors'!$B11) -> 4 | S11: =YEAR('data on outstanding creditors'!$B11) -> 2025 | T11: ='data on outstanding creditors'!$C11&" "&'data on outstanding creditors'!$D11&" "&TEXT('data on outstanding creditors'!$E11,"#,##0.00") -> บ.เซ็นทรัลโพลีเทรดดิ้ง 31i25019285 8,250.00
B12: 45765 | C12: บ.เซ็นทรัลโพลีเทรดดิ้ง | D12: 31i25019846 | E12: 35000 | F12: 35000 | H12: ='data on outstanding creditors'!$E12-'data on outstanding creditors'!$F12-'data on outstanding creditors'!$G12 -> 0 | I12: 45938 | M12: 2.1.01 ค่ายา | N12: กลุ่มงาน เภสัชกรรม | O12: ='data on outstanding creditors'!$E12*100/107 -> 32710.28 | P12: ='data on outstanding creditors'!$E12-'data on outstanding creditors'!$O12 -> 2289.7196 | Q12: =DAY('data on outstanding creditors'!$B12) -> 18 | R12: =MONTH('data on outstanding creditors'!$B12) -> 4 | S12: =YEAR('data on outstanding creditors'!$B12) -> 2025 | T12: ='data on outstanding creditors'!$C12&" "&'data on outstanding creditors'!$D12&" "&TEXT('data on outstanding creditors'!$E12,"#,##0.00") -> บ.เซ็นทรัลโพลีเทรดดิ้ง 31i25019846 35,000.00
B13: 45765 | C13: บ.เซ็นทรัลโพลีเทรดดิ้ง | D13: 31i25020207 | E13: 8750 | F13: 8750 | H13: ='data on outstanding creditors'!$E13-'data on outstanding creditors'!$F13-'data on outstanding creditors'!$G13 -> 0 | I13: 45938 | M13: 2.1.01 ค่ายา | N13: กลุ่มงาน เภสัชกรรม | O13: ='data on outstanding creditors'!$E13*100/107 -> 8177.5701 | P13: ='data on outstanding creditors'!$E13-'data on outstanding creditors'!$O13 -> 572.42991 | Q13: =DAY('data on outstanding creditors'!$B13) -> 18 | R13: =MONTH('data on outstanding creditors'!$B13) -> 4 | S13: =YEAR('data on outstanding creditors'!$B13) -> 2025 | T13: ='data on outstanding creditors'!$C13&" "&'data on outstanding creditors'!$D13&" "&TEXT('data on outstanding creditors'!$E13,"#,##0.00") -> บ.เซ็นทรัลโพลีเทรดดิ้ง 31i25020207 8,750.00
... B19: 45687 | C19: บ.เอ็นราฟ-โนเนียส เมดิคอล อิควิปเมนท์ | D19: I6801/00064 | E19: 6000 | F19: 6000 | H19: ='data on outstanding creditors'!$E19-'data on outstanding creditors'!$F19-'data on outstanding creditors'!$G19 -> 0 | I19: 45938 | M19: 2.1.03 ค่าวัสดุการแพทย์ | N19: กลุ่มงาน เวชกรรมฟื้นฟู | O19: ='data on outstanding creditors'!$E19*100/107 -> 5607.4766 | P19: ='data on outstanding creditors'!$E19-'data on outstanding creditors'!$O19 -> 392.52336 | Q19: =DAY('data on outstanding creditors'!$B19) -> 30 | R19: =MONTH('data on outstanding creditors'!$B19) -> 1 | S19: =YEAR('data on outstanding creditors'!$B19) -> 2025 | T19: ='data on outstanding creditors'!$C19&" "&'data on outstanding creditors'!$D19&" "&TEXT('data on outstanding creditors'!$E19,"#,##0.00") -> บ.เอ็นราฟ-โนเนียส เมดิคอล อิควิปเมนท์ I6801/00064 6,000.00
A20: 1031-68 | B20: 45869 | C20: บ.เดอะคอนเนคเซอร์วิสเซล | D20: BL2025070058 | E20: 138638.8 | F20: 138638.8 | H20: ='data on outstanding creditors'!$E20-'data on outstanding creditors'!$F20-'data on outstanding creditors'!$G20 -> 0 | I20: 45938 | M20: 2.2.12 ค่าจ้างเหมาบริการอื่น (เบ็ดเตล็ด) | N20: กลุ่มงาน พัสดุ | O20: ='data on outstanding creditors'!$E20*100/107 -> 129568.97 | P20: ='data on outstanding creditors'!$E20-'data on outstanding creditors'!$O20 -> 9069.828 | Q20: =DAY('data on outstanding creditors'!$B20) -> 31 | R20: =MONTH('data on outstanding creditors'!$B20) -> 7 | S20: =YEAR('data on outstanding creditors'!$B20) -> 2025 | T20: ='data on outstanding creditors'!$C20&" "&'data on outstanding creditors'!$D20&" "&TEXT('data on outstanding creditors'!$E20,"#,##0.00") -> บ.เดอะคอนเนคเซอร์วิสเซล BL2025070058 138,638.80
A21: 1031-68 | B21: 45901 | C21: บ.เดอะคอนเนคเซอร์วิสเซล | D21: BL2025080063 | E21: 207955.17 | F21: 207955.17 | H21: ='data on outstanding creditors'!$E21-'data on outstanding creditors'!$F21-'data on outstanding creditors'!$G21 -> 0 | I21: 45938 | M21: 2.2.12 ค่าจ้างเหมาบริการอื่น (เบ็ดเตล็ด) | N21: กลุ่มงาน พัสดุ | O21: ='data on outstanding creditors'!$E21*100/107 -> 194350.63 | P21: ='data on outstanding creditors'!$E21-'data on outstanding creditors'!$O21 -> 13604.544 | Q21: =DAY('data on outstanding creditors'!$B21) -> 1 | R21: =MONTH('data on outstanding creditors'!$B21) -> 9 | S21: =YEAR('data on outstanding creditors'!$B21) -> 2025 | T21: ='data on outstanding creditors'!$C21&" "&'data on outstanding creditors'!$D21&" "&TEXT('data on outstanding creditors'!$E21,"#,##0.00") -> บ.เดอะคอนเนคเซอร์วิสเซล BL2025080063 207,955.17
A22: 1919-68 | B22: 45807 | C22: หจก.ส.เรืองโรจน์สระบุรี | D22: IV92173/030668 | E22: 139177.5 | F22: 139177.5 | H22: ='data on outstanding creditors'!$E22-'data on outstanding creditors'!$F22-'data on outstanding creditors'!$G22 -> 0 | I22: 45938 | M22: 2.2.13 ค่าจ้างเหมาบริการอื่น | N22: กลุ่มงาน พัสดุ | O22: ='data on outstanding creditors'!$E22*100/107 -> 130072.43 | P22: ='data on outstanding creditors'!$E22-'data on outstanding creditors'!$O22 -> 9105.0701 | Q22: =DAY('data on outstanding creditors'!$B22) -> 30 | R22: =MONTH('data on outstanding creditors'!$B22) -> 5 | S22: =YEAR('data on outstanding creditors'!$B22) -> 2025 | T22: ='data on outstanding creditors'!$C22&" "&'data on outstanding creditors'!$D22&" "&TEXT('data on outstanding creditors'!$E22,"#,##0.00") -> หจก.ส.เรืองโรจน์สระบุรี IV92173/030668 139,177.50
A23: 2539-68 | B23: 45852 | C23: บ.ห้องปฏิบัติการกลาง(ประเทศไทย) | D23: SIVKK-2506-0712 | E23: 3177.9 | F23: 3177.9 | H23: ='data on outstanding creditors'!$E23-'data on outstanding creditors'!$F23-'data on outstanding creditors'!$G23 -> 0 | I23: 45938 | M23: 2.2.17 ค่าจ้างตรวจ(LAB) | N23: กลุ่มงาน พัสดุ | O23: ='data on outstanding creditors'!$E23*100/107 -> 2970 | P23: ='data on outstanding creditors'!$E23-'data on outstanding creditors'!$O23 -> 207.9 | Q23: =DAY('data on outstanding creditors'!$B23) -> 14 | R23: =MONTH('data on outstanding creditors'!$B23) -> 7 | S23: =YEAR('data on outstanding creditors'!$B23) -> 2025 | T23: ='data on outstanding creditors'!$C23&" "&'data on outstanding creditors'!$D23&" "&TEXT('data on outstanding creditors'!$E23,"#,##0.00") -> บ.ห้องปฏิบัติการกลาง(ประเทศไทย) SIVKK-2506-0712 3,177.90
B24: 45673 | C24: บ.ไทย เฮลท์ อิมเมจจิ้ง MRI สิทธิ จ่ายตรง | D24: 001/028 11/67 | E24: 35100 | F24: 35100 | H24: ='data on outstanding creditors'!$E24-'data on outstanding creditors'!$F24-'data on outstanding creditors'!$G24 -> 0 | I24: 45938 | M24: 2.2.18 ค่าจ้างตรวจ(X-RAY) | N24: กลุ่มงาน พัสดุ | O24: ='data on outstanding creditors'!$E24*100/107 -> 32803.738 | P24: ='data on outstanding creditors'!$E24-'data on outstanding creditors'!$O24 -> 2296.2617 | Q24: =DAY('data on outstanding creditors'!$B24) -> 16 | R24: =MONTH('data on outstanding creditors'!$B24) -> 1 | S24: =YEAR('data on outstanding creditors'!$B24) -> 2025 | T24: ='data on outstanding creditors'!$C24&" "&'data on outstanding creditors'!$D24&" "&TEXT('data on outstanding creditors'!$E24,"#,##0.00") -> บ.ไทย เฮลท์ อิมเมจจิ้ง MRI สิทธิ จ่ายตรง 001/028 11/67 35,100.00
B25: 45673 | C25: บ.ไทย เฮลท์ อิมเมจจิ้ง MRI สิทธิ จ่ายตรง | D25: 001/033 11/67 | E25: 134850 | F25: 134850 | H25: ='data on outstanding creditors'!$E25-'data on outstanding creditors'!$F25-'data on outstanding creditors'!$G25 -> 0 | I25: 45938 | M25: 2.2.18 ค่าจ้างตรวจ(X-RAY) | N25: กลุ่มงาน พัสดุ | O25: ='data on outstanding creditors'!$E25*100/107 -> 126028.04 | P25: ='data on outstanding creditors'!$E25-'data on outstanding creditors'!$O25 -> 8821.9626 | Q25: =DAY('data on outstanding creditors'!$B25) -> 16 | R25: =MONTH('data on outstanding creditors'!$B25) -> 1 | S25: =YEAR('data on outstanding creditors'!$B25) -> 2025 | T25: ='data on outstanding creditors'!$C25&" "&'data on outstanding creditors'!$D25&" "&TEXT('data on outstanding creditors'!$E25,"#,##0.00") -> บ.ไทย เฮลท์ อิมเมจจิ้ง MRI สิทธิ จ่ายตรง 001/033 11/67 134,850.00
B26: 45673 | C26: บ.ไทย เฮลท์ อิมเมจจิ้ง MRI สิทธิ จ่ายตรง | D26: 001/034 11/67 | E26: 75550 | F26: 75550 | H26: ='data on outstanding creditors'!$E26-'data on outstanding creditors'!$F26-'data on outstanding creditors'!$G26 -> 0 | I26: 45938 | M26: 2.2.18 ค่าจ้างตรวจ(X-RAY) | N26: กลุ่มงาน พัสดุ | O26: ='data on outstanding creditors'!$E26*100/107 -> 70607.477 | P26: ='data on outstanding creditors'!$E26-'data on outstanding creditors'!$O26 -> 4942.5234 | Q26: =DAY('data on outstanding creditors'!$B26) -> 16 | R26: =MONTH('data on outstanding creditors'!$B26) -> 1 | S26: =YEAR('data on outstanding creditors'!$B26) -> 2025 | T26: ='data on outstanding creditors'!$C26&" "&'data on outstanding creditors'!$D26&" "&TEXT('data on outstanding creditors'!$E26,"#,##0.00") -> บ.ไทย เฮลท์ อิมเมจจิ้ง MRI สิทธิ จ่ายตรง 001/034 11/67 75,550.00
B27: 45673 | C27: บ.ไทย เฮลท์ อิมเมจจิ้ง MRI สิทธิ ชำระเงิน | D27: 001/031 11/67 | E27: 13600 | F27: 13600 | H27: ='data on outstanding creditors'!$E27-'data on outstanding creditors'!$F27-'data on outstanding creditors'!$G27 -> 0 | I27: 45938 | M27: 2.2.18 ค่าจ้างตรวจ(X-RAY) | N27: กลุ่มงาน พัสดุ | O27: ='data on outstanding creditors'!$E27*100/107 -> 12710.28 | P27: ='data on outstanding creditors'!$E27-'data on outstanding creditors'!$O27 -> 889.71963 | Q27: =DAY('data on outstanding creditors'!$B27) -> 16 | R27: =MONTH('data on outstanding creditors'!$B27) -> 1 | S27: =YEAR('data on outstanding creditors'!$B27) -> 2025 | T27: ='data on outstanding creditors'!$C27&" "&'data on outstanding creditors'!$D27&" "&TEXT('data on outstanding creditors'!$E27,"#,##0.00") -> บ.ไทย เฮลท์ อิมเมจจิ้ง MRI สิทธิ ชำระเงิน 001/031 11/67 13,600.00
B28: 45673 | C28: บ.ไทย เฮลท์ อิมเมจจิ้ง MRI สิทธิ พรบ. | D28: 001/030 11/67 | E28: 33950 | F28: 33950 | H28: ='data on outstanding creditors'!$E28-'data on outstanding creditors'!$F28-'data on outstanding creditors'!$G28 -> 0 | I28: 45938 | M28: 2.2.18 ค่าจ้างตรวจ(X-RAY) | N28: กลุ่มงาน พัสดุ | O28: ='data on outstanding creditors'!$E28*100/107 -> 31728.972 | P28: ='data on outstanding creditors'!$E28-'data on outstanding creditors'!$O28 -> 2221.028 | Q28: =DAY('data on outstanding creditors'!$B28) -> 16 | R28: =MONTH('data on outstanding creditors'!$B28) -> 1 | S28: =YEAR('data on outstanding creditors'!$B28) -> 2025 | T28: ='data on outstanding creditors'!$C28&" "&'data on outstanding creditors'!$D28&" "&TEXT('data on outstanding creditors'!$E28,"#,##0.00") -> บ.ไทย เฮลท์ อิมเมจจิ้ง MRI สิทธิ พรบ. 001/030 11/67 33,950.00
B29: 45673 | C29: บ.ไทย เฮลท์ อิมเมจจิ้ง MRI สิทธิ สปสช | D29: 001/027 11/67 | E29: 76950 | F29: 76950 | H29: ='data on outstanding creditors'!$E29-'data on outstanding creditors'!$F29-'data on outstanding creditors'!$G29 -> 0 | I29: 45938 | M29: 2.2.18 ค่าจ้างตรวจ(X-RAY) | N29: กลุ่มงาน พัสดุ | O29: ='data on outstanding creditors'!$E29*100/107 -> 71915.888 | P29: ='data on outstanding creditors'!$E29-'data on outstanding creditors'!$O29 -> 5034.1121 | Q29: =DAY('data on outstanding creditors'!$B29) -> 16 | R29: =MONTH('data on outstanding creditors'!$B29) -> 1 | S29: =YEAR('data on outstanding creditors'!$B29) -> 2025 | T29: ='data on outstanding creditors'!$C29&" "&'data on outstanding creditors'!$D29&" "&TEXT('data on outstanding creditors'!$E29,"#,##0.00") -> บ.ไทย เฮลท์ อิมเมจจิ้ง MRI สิทธิ สปสช 001/027 11/67 76,950.00
B30: 45673 | C30: บ.ไทย เฮลท์ อิมเมจจิ้ง MRI สิทธิ สปสช | D30: 001/035 11/67 | E30: 142200 | F30: 142200 | H30: ='data on outstanding creditors'!$E30-'data on outstanding creditors'!$F30-'data on outstanding creditors'!$G30 -> 0 | I30: 45938 | M30: 2.2.18 ค่าจ้างตรวจ(X-RAY) | N30: กลุ่มงาน พัสดุ | O30: ='data on outstanding creditors'!$E30*100/107 -> 132897.2 | P30: ='data on outstanding creditors'!$E30-'data on outstanding creditors'!$O30 -> 9302.8037 | Q30: =DAY('data on outstanding creditors'!$B30) -> 16 | R30: =MONTH('data on outstanding creditors'!$B30) -> 1 | S30: =YEAR('data on outstanding creditors'!$B30) -> 2025 | T30: ='data on outstanding creditors'!$C30&" "&'data on outstanding creditors'!$D30&" "&TEXT('data on outstanding creditors'!$E30,"#,##0.00") -> บ.ไทย เฮลท์ อิมเมจจิ้ง MRI สิทธิ สปสช 001/035 11/67 142,200.00
B31: 45673 | C31: บ.ไทย เฮลท์ อิมเมจจิ้ง MRI สิทธิ สปสช | D31: 001/036 11/67 | E31: 119700 | F31: 119700 | H31: ='data on outstanding creditors'!$E31-'data on outstanding creditors'!$F31-'data on outstanding creditors'!$G31 -> 0 | I31: 45938 | M31: 2.2.18 ค่าจ้างตรวจ(X-RAY) | N31: กลุ่มงาน พัสดุ | O31: ='data on outstanding creditors'!$E31*100/107 -> 111869.16 | P31: ='data on outstanding creditors'!$E31-'data on outstanding creditors'!$O31 -> 7830.8411 | Q31: =DAY('data on outstanding creditors'!$B31) -> 16 | R31: =MONTH('data on outstanding creditors'!$B31) -> 1 | S31: =YEAR('data on outstanding creditors'!$B31) -> 2025 | T31: ='data on outstanding creditors'!$C31&" "&'data on outstanding creditors'!$D31&" "&TEXT('data on outstanding creditors'!$E31,"#,##0.00") -> บ.ไทย เฮลท์ อิมเมจจิ้ง MRI สิทธิ สปสช 001/036 11/67 119,700.00
B32: 45688 | C32: บ.ไทย เฮลท์ อิมเมจจิ้ง MRI สิทธิ จ่ายตรง | D32: 001/039 12/67 | E32: 18000 | F32: 18000 | H32: ='data on outstanding creditors'!$E32-'data on outstanding creditors'!$F32-'data on outstanding creditors'!$G32 -> 0 | I32: 45938 | M32: 2.2.18 ค่าจ้างตรวจ(X-RAY) | N32: กลุ่มงาน พัสดุ | O32: ='data on outstanding creditors'!$E32*100/107 -> 16822.43 | P32: ='data on outstanding creditors'!$E32-'data on outstanding creditors'!$O32 -> 1177.5701 | Q32: =DAY('data on outstanding creditors'!$B32) -> 31 | R32: =MONTH('data on outstanding creditors'!$B32) -> 1 | S32: =YEAR('data on outstanding creditors'!$B32) -> 2025 | T32: ='data on outstanding creditors'!$C32&" "&'data on outstanding creditors'!$D32&" "&TEXT('data on outstanding creditors'!$E32,"#,##0.00") -> บ.ไทย เฮลท์ อิมเมจจิ้ง MRI สิทธิ จ่ายตรง 001/039 12/67 18,000.00
B33: 45688 | C33: บ.ไทย เฮลท์ อิมเมจจิ้ง MRI สิทธิ จ่ายตรง | D33: 001/042 12/67 | E33: 120450 | F33: 120450 | H33: ='data on outstanding creditors'!$E33-'data on outstanding creditors'!$F33-'data on outstanding creditors'!$G33 -> 0 | I33: 45938 | M33: 2.2.18 ค่าจ้างตรวจ(X-RAY) | N33: กลุ่มงาน พัสดุ | O33: ='data on outstanding creditors'!$E33*100/107 -> 112570.09 | P33: ='data on outstanding creditors'!$E33-'data on outstanding creditors'!$O33 -> 7879.9065 | Q33: =DAY('data on outstanding creditors'!$B33) -> 31 | R33: =MONTH('data on outstanding creditors'!$B33) -> 1 | S33: =YEAR('data on outstanding creditors'!$B33) -> 2025 | T33: ='data on outstanding creditors'!$C33&" "&'data on outstanding creditors'!$D33&" "&TEXT('data on outstanding creditors'!$E33,"#,##0.00") -> บ.ไทย เฮลท์ อิมเมจจิ้ง MRI สิทธิ จ่ายตรง 001/042 12/67 120,450.00
B34: 45688 | C34: บ.ไทย เฮลท์ อิมเมจจิ้ง MRI สิทธิ จ่ายตรง | D34: 001/043 12/67 | E34: 66150 | F34: 66150 | H34: ='data on outstanding creditors'!$E34-'data on outstanding creditors'!$F34-'data on outstanding creditors'!$G34 -> 0 | I34: 45938 | M34: 2.2.18 ค่าจ้างตรวจ(X-RAY) | N34: กลุ่มงาน พัสดุ | O34: ='data on outstanding creditors'!$E34*100/107 -> 61822.43 | P34: ='data on outstanding creditors'!$E34-'data on outstanding creditors'!$O34 -> 4327.5701 | Q34: =DAY('data on outstanding creditors'!$B34) -> 31 | R34: =MONTH('data on outstanding creditors'!$B34) -> 1 | S34: =YEAR('data on outstanding creditors'!$B34) -> 2025 | T34: ='data on outstanding creditors'!$C34&" "&'data on outstanding creditors'!$D34&" "&TEXT('data on outstanding creditors'!$E34,"#,##0.00") -> บ.ไทย เฮลท์ อิมเมจจิ้ง MRI สิทธิ จ่ายตรง 001/043 12/67 66,150.00
B35: 45688 | C35: บ.ไทย เฮลท์ อิมเมจจิ้ง MRI สิทธิ พรบ. | D35: 001/041 12/67 | E35: 20400 | F35: 20400 | H35: ='data on outstanding creditors'!$E35-'data on outstanding creditors'!$F35-'data on outstanding creditors'!$G35 -> 0 | I35: 45938 | M35: 2.2.18 ค่าจ้างตรวจ(X-RAY) | N35: กลุ่มงาน พัสดุ | O35: ='data on outstanding creditors'!$E35*100/107 -> 19065.421 | P35: ='data on outstanding creditors'!$E35-'data on outstanding creditors'!$O35 -> 1334.5794 | Q35: =DAY('data on outstanding creditors'!$B35) -> 31 | R35: =MONTH('data on outstanding creditors'!$B35) -> 1 | S35: =YEAR('data on outstanding creditors'!$B35) -> 2025 | T35: ='data on outstanding creditors'!$C35&" "&'data on outstanding creditors'!$D35&" "&TEXT('data on outstanding creditors'!$E35,"#,##0.00") -> บ.ไทย เฮลท์ อิมเมจจิ้ง MRI สิทธิ พรบ. 001/041 12/67 20,400.00
... B40: 45693 | C40: บ.ไทย เฮลท์ อิมเมจจิ้ง MMG สิทธิ จ่ายตรง | D40: 016/752 11/67 | E40: 19200 | F40: 19200 | H40: ='data on outstanding creditors'!$E40-'data on outstanding creditors'!$F40-'data on outstanding creditors'!$G40 -> 0 | I40: 45938 | M40: 2.2.18 ค่าจ้างตรวจ(X-RAY) | N40: กลุ่มงาน พัสดุ | O40: ='data on outstanding creditors'!$E40*100/107 -> 17943.925 | P40: ='data on outstanding creditors'!$E40-'data on outstanding creditors'!$O40 -> 1256.0748 | Q40: =DAY('data on outstanding creditors'!$B40) -> 5 | R40: =MONTH('data on outstanding creditors'!$B40) -> 2 | S40: =YEAR('data on outstanding creditors'!$B40) -> 2025 | T40: ='data on outstanding creditors'!$C40&" "&'data on outstanding creditors'!$D40&" "&TEXT('data on outstanding creditors'!$E40,"#,##0.00") -> บ.ไทย เฮลท์ อิมเมจจิ้ง MMG สิทธิ จ่ายตรง 016/752 11/67 19,200.00
A41: 1665-68 | B41: 45818 | C41: ร้าน สมาร์ทดอกคิวเมนท์ | D41: S680005 | E41: 114000 | F41: 114000 | H41: ='data on outstanding creditors'!$E41-'data on outstanding creditors'!$F41-'data on outstanding creditors'!$G41 -> 0 | I41: 45938 | M41: 2.3.02 ค่าครุภัณฑ์สำนักงาน | N41: กลุ่มงาน พัสดุ | O41: ='data on outstanding creditors'!$E41*100/107 -> 106542.06 | P41: ='data on outstanding creditors'!$E41-'data on outstanding creditors'!$O41 -> 7457.9439 | Q41: =DAY('data on outstanding creditors'!$B41) -> 10 | R41: =MONTH('data on outstanding creditors'!$B41) -> 6 | S41: =YEAR('data on outstanding creditors'!$B41) -> 2025 | T41: ='data on outstanding creditors'!$C41&" "&'data on outstanding creditors'!$D41&" "&TEXT('data on outstanding creditors'!$E41,"#,##0.00") -> ร้าน สมาร์ทดอกคิวเมนท์ S680005 114,000.00
A42: 741-68 | B42: 45845 | C42: บ.ดูวอนไทย | D42: DW088/2568 | E42: 39000 | F42: 39000 | H42: ='data on outstanding creditors'!$E42-'data on outstanding creditors'!$F42-'data on outstanding creditors'!$G42 -> 0 | I42: 45938 | M42: 2.3.08 ค่าครุภัณฑ์วิทยาศาสตร์การแพทย์ | N42: กลุ่มงาน พัสดุ | O42: ='data on outstanding creditors'!$E42*100/107 -> 36448.598 | P42: ='data on outstanding creditors'!$E42-'data on outstanding creditors'!$O42 -> 2551.4019 | Q42: =DAY('data on outstanding creditors'!$B42) -> 7 | R42: =MONTH('data on outstanding creditors'!$B42) -> 7 | S42: =YEAR('data on outstanding creditors'!$B42) -> 2025 | T42: ='data on outstanding creditors'!$C42&" "&'data on outstanding creditors'!$D42&" "&TEXT('data on outstanding creditors'!$E42,"#,##0.00") -> บ.ดูวอนไทย DW088/2568 39,000.00
A43: 3410-68 | B43: 45889 | C43: หจก.นางรองคอมพิวเตอร์ เซ็นเตอร์ | D43: IV2508-065644 | E43: 2940 | F43: 2940 | H43: ='data on outstanding creditors'!$E43-'data on outstanding creditors'!$F43-'data on outstanding creditors'!$G43 -> 0 | I43: 45939 | M43: 2.1.05 ค่าวัสดุคอมพิวเตอร์ | N43: กลุ่มงาน พัสดุ | O43: ='data on outstanding creditors'!$E43*100/107 -> 2747.6636 | P43: ='data on outstanding creditors'!$E43-'data on outstanding creditors'!$O43 -> 192.33645 | Q43: =DAY('data on outstanding creditors'!$B43) -> 20 | R43: =MONTH('data on outstanding creditors'!$B43) -> 8 | S43: =YEAR('data on outstanding creditors'!$B43) -> 2025 | T43: ='data on outstanding creditors'!$C43&" "&'data on outstanding creditors'!$D43&" "&TEXT('data on outstanding creditors'!$E43,"#,##0.00") -> หจก.นางรองคอมพิวเตอร์ เซ็นเตอร์ IV2508-065644 2,940.00
A44: 3192-68 | B44: 45894 | C44: หจก.นางรองคอมพิวเตอร์ เซ็นเตอร์ | D44: IV2508-065740 | E44: 1700 | F44: 1700 | H44: ='data on outstanding creditors'!$E44-'data on outstanding creditors'!$F44-'data on outstanding creditors'!$G44 -> 0 | I44: 45939 | M44: 2.1.05 ค่าวัสดุคอมพิวเตอร์ | N44: กลุ่มงาน พัสดุ | O44: ='data on outstanding creditors'!$E44*100/107 -> 1588.785 | P44: ='data on outstanding creditors'!$E44-'data on outstanding creditors'!$O44 -> 111.21495 | Q44: =DAY('data on outstanding creditors'!$B44) -> 25 | R44: =MONTH('data on outstanding creditors'!$B44) -> 8 | S44: =YEAR('data on outstanding creditors'!$B44) -> 2025 | T44: ='data on outstanding creditors'!$C44&" "&'data on outstanding creditors'!$D44&" "&TEXT('data on outstanding creditors'!$E44,"#,##0.00") -> หจก.นางรองคอมพิวเตอร์ เซ็นเตอร์ IV2508-065740 1,700.00
A45: 3320-68 | B45: 45905 | C45: หจก.นางรองคอมพิวเตอร์ เซ็นเตอร์ | D45: IV2509-066191 | E45: 1470 | F45: 1470 | H45: ='data on outstanding creditors'!$E45-'data on outstanding creditors'!$F45-'data on outstanding creditors'!$G45 -> 0 | I45: 45939 | M45: 2.1.05 ค่าวัสดุคอมพิวเตอร์ | N45: กลุ่มงาน พัสดุ | O45: ='data on outstanding creditors'!$E45*100/107 -> 1373.8318 | P45: ='data on outstanding creditors'!$E45-'data on outstanding creditors'!$O45 -> 96.168224 | Q45: =DAY('data on outstanding creditors'!$B45) -> 5 | R45: =MONTH('data on outstanding creditors'!$B45) -> 9 | S45: =YEAR('data on outstanding creditors'!$B45) -> 2025 | T45: ='data on outstanding creditors'!$C45&" "&'data on outstanding creditors'!$D45&" "&TEXT('data on outstanding creditors'!$E45,"#,##0.00") -> หจก.นางรองคอมพิวเตอร์ เซ็นเตอร์ IV2509-066191 1,470.00
A46: 4010-68 | B46: 45924 | C46: หจก.ทวีศักดิ์การไฟฟ้า 2018 | D46: TN00003003 | E46: 600 | F46: 600 | H46: ='data on outstanding creditors'!$E46-'data on outstanding creditors'!$F46-'data on outstanding creditors'!$G46 -> 0 | I46: 45939 | M46: 2.1.05 ค่าวัสดุคอมพิวเตอร์ | N46: กลุ่มงาน พัสดุ | O46: ='data on outstanding creditors'!$E46*100/107 -> 560.74766 | P46: ='data on outstanding creditors'!$E46-'data on outstanding creditors'!$O46 -> 39.252336 | Q46: =DAY('data on outstanding creditors'!$B46) -> 24 | R46: =MONTH('data on outstanding creditors'!$B46) -> 9 | S46: =YEAR('data on outstanding creditors'!$B46) -> 2025 | T46: ='data on outstanding creditors'!$C46&" "&'data on outstanding creditors'!$D46&" "&TEXT('data on outstanding creditors'!$E46,"#,##0.00") -> หจก.ทวีศักดิ์การไฟฟ้า 2018 TN00003003 600.00
A47: 1662-68 | B47: 45834 | C47: บ.ก้ำหมงเครื่องครัว | D47: INV680626004 | E47: 2934 | F47: 2934 | H47: ='data on outstanding creditors'!$E47-'data on outstanding creditors'!$F47-'data on outstanding creditors'!$G47 -> 0 | I47: 45939 | M47: 2.1.06 ค่าวัสดุสำนักงาน | N47: กลุ่มงาน พัสดุ | O47: ='data on outstanding creditors'!$E47*100/107 -> 2742.0561 | P47: ='data on outstanding creditors'!$E47-'data on outstanding creditors'!$O47 -> 191.94393 | Q47: =DAY('data on outstanding creditors'!$B47) -> 26 | R47: =MONTH('data on outstanding creditors'!$B47) -> 6 | S47: =YEAR('data on outstanding creditors'!$B47) -> 2025 | T47: ='data on outstanding creditors'!$C47&" "&'data on outstanding creditors'!$D47&" "&TEXT('data on outstanding creditors'!$E47,"#,##0.00") -> บ.ก้ำหมงเครื่องครัว INV680626004 2,934.00
A48: 3234-68 | B48: 45898 | C48: หจก.ทวีศักดิ์การไฟฟ้า 2018 | D48: TN00002955 | E48: 3600 | F48: 3600 | H48: ='data on outstanding creditors'!$E48-'data on outstanding creditors'!$F48-'data on outstanding creditors'!$G48 -> 0 | I48: 45939 | M48: 2.1.06 ค่าวัสดุสำนักงาน | N48: กลุ่มงาน พัสดุ | O48: ='data on outstanding creditors'!$E48*100/107 -> 3364.486 | P48: ='data on outstanding creditors'!$E48-'data on outstanding creditors'!$O48 -> 235.51402 | Q48: =DAY('data on outstanding creditors'!$B48) -> 29 | R48: =MONTH('data on outstanding creditors'!$B48) -> 8 | S48: =YEAR('data on outstanding creditors'!$B48) -> 2025 | T48: ='data on outstanding creditors'!$C48&" "&'data on outstanding creditors'!$D48&" "&TEXT('data on outstanding creditors'!$E48,"#,##0.00") -> หจก.ทวีศักดิ์การไฟฟ้า 2018 TN00002955 3,600.00
A49: 3488-68 | B49: 45915 | C49: นาย อิฐธิเดช นาแพง | D49: 01/01 | E49: 3850 | F49: 3850 | H49: ='data on outstanding creditors'!$E49-'data on outstanding creditors'!$F49-'data on outstanding creditors'!$G49 -> 0 | I49: 45939 | M49: 2.1.06 ค่าวัสดุสำนักงาน | N49: กลุ่มงาน พัสดุ | O49: ='data on outstanding creditors'!$E49*100/107 -> 3598.1308 | P49: ='data on outstanding creditors'!$E49-'data on outstanding creditors'!$O49 -> 251.86916 | Q49: =DAY('data on outstanding creditors'!$B49) -> 15 | R49: =MONTH('data on outstanding creditors'!$B49) -> 9 | S49: =YEAR('data on outstanding creditors'!$B49) -> 2025 | T49: ='data on outstanding creditors'!$C49&" "&'data on outstanding creditors'!$D49&" "&TEXT('data on outstanding creditors'!$E49,"#,##0.00") -> นาย อิฐธิเดช นาแพง 01/01 3,850.00
...

Sheet Sheet1
